Workbook

Sheet Raw Data
A1: Shipment ID | B1: Order Date | C1: Customer Type | D1: Destination Country | E1: Product Category | F1: Carrier | G1: Promised Delivery Date | H1: Actual Delivery Date | I1: Delay Days | J1: On Time | K1: Delay Reason | L1: Order Value EUR | M1: Order Month
A2: SH0001 | B2: 46231.917 | C2: Retail Chain | D2: United Kingdom | E2: DVD | F2: PostNL | G2: 46240.917 | H2: 46239.917 | I2: =H2-G2 | J2: =IF(I2<=0,"Yes","No") | L2: 1279 | M2: =TEXT(B2,"mmm-yy")
A3: SH0002 | B3: 46217.917 | C3: Online Retailer | D3: United States | E3: Merchandise | F3: PostNL | G3: 46225.917 | H3: 46224.917 | I3: =H3-G3 | J3: =IF(I3<=0,"Yes","No") | L3: 282 | M3: =TEXT(B3,"mmm-yy")
A4: SH0003 | B4: 46200.917 | C4: Retail Chain | D4: United Kingdom | E4: Vinyl | F4: DPD | G4: 46209.917 | H4: 46213.917 | I4: =H4-G4 | J4: =IF(I4<=0,"Yes","No") | K4: Customs hold | L4: 1376 | M4: =TEXT(B4,"mmm-yy")
A5: SH0004 | B5: 46170.917 | C5: Independent Store | D5: United States | E5: Vinyl | F5: DHL | G5: 46178.917 | H5: 46187.917 | I5: =H5-G5 | J5: =IF(I5<=0,"Yes","No") | K5: Stock shortage | L5: 1385 | M5: =TEXT(B5,"mmm-yy")
A6: SH0005 | B6: 46150.917 | C6: Retail Chain | D6: United States | E6: CD | F6: GLS | G6: 46153.917 | H6: 46153.917 | I6: =H6-G6 | J6: =IF(I6<=0,"Yes","No") | L6: 172 | M6: =TEXT(B6,"mmm-yy")
A7: SH0006 | B7: 46120.917 | C7: Retail Chain | D7: Belgium | E7: Vinyl | F7: UPS | G7: 46126.917 | H7: 46125.917 | I7: =H7-G7 | J7: =IF(I7<=0,"Yes","No") | L7: 1117 | M7: =TEXT(B7,"mmm-yy")
A8: SH0007 | B8: 46155.917 | C8: Retail Chain | D8: United Kingdom | E8: Merchandise | F8: DPD | G8: 46162.917 | H8: 46161.917 | I8: =H8-G8 | J8: =IF(I8<=0,"Yes","No") | L8: 1148 | M8: =TEXT(B8,"mmm-yy")
A9: SH0008 | B9: 46153.917 | C9: Retail Chain | D9: Netherlands | E9: Vinyl | F9: DPD | G9: 46161.917 | H9: 46161.917 | I9: =H9-G9 | J9: =IF(I9<=0,"Yes","No") | L9: 704 | M9: =TEXT(B9,"mmm-yy")
A10: SH0009 | B10: 46149.917 | C10: Retail Chain | D10: France | E10: Vinyl | F10: PostNL | G10: 46159.917 | H10: 46162.917 | I10: =H10-G10 | J10: =IF(I10<=0,"Yes","No") | K10: Customs hold | L10: 873 | M10: =TEXT(B10,"mmm-yy")
A11: SH0010 | B11: 46214.917 | C11: Retail Chain | D11: United States | E11: Merchandise | F11: PostNL | G11: 46219.917 | H11: 46218.917 | I11: =H11-G11 | J11: =IF(I11<=0,"Yes","No") | L11: 302 | M11: =TEXT(B11,"mmm-yy")
A12: SH0011 | B12: 46151.917 | C12: Independent Store | D12: Netherlands | E12: Merchandise | F12: DPD | G12: 46157.917 | H12: 46157.917 | I12: =H12-G12 | J12: =IF(I12<=0,"Yes","No") | L12: 1012 | M12: =TEXT(B12,"mmm-yy")
A13: SH0012 | B13: 46221.917 | C13: Online Retailer | D13: France | E13: CD | F13: GLS | G13: 46231.917 | H13: 46231.917 | I13: =H13-G13 | J13: =IF(I13<=0,"Yes","No") | L13: 1685 | M13: =TEXT(B13,"mmm-yy")
A14: SH0013 | B14: 46186.917 | C14: Retail Chain | D14: Belgium | E14: Merchandise | F14: DPD | G14: 46195.917 | H14: 46203.917 | I14: =H14-G14 | J14: =IF(I14<=0,"Yes","No") | K14: Documentation error | L14: 1400 | M14: =TEXT(B14,"mmm-yy")
A15: SH0014 | B15: 46172.917 | C15: Independent Store | D15: France | E15: Vinyl | F15: GLS | G15: 46180.917 | H15: 46180.917 | I15: =H15-G15 | J15: =IF(I15<=0,"Yes","No") | L15: 1314 | M15: =TEXT(B15,"mmm-yy")
A16: SH0015 | B16: 46120.917 | C16: Online Retailer | D16: United States | E16: Vinyl | F16: DPD | G16: 46126.917 | H16: 46126.917 | I16: =H16-G16 | J16: =IF(I16<=0,"Yes","No") | L16: 1190 | M16: =TEXT(B16,"mmm-yy")
A17: SH0016 | B17: 46234.917 | C17: Online Retailer | D17: France | E17: CD | F17: UPS | G17: 46241.917 | H17: 46244.917 | I17: =H17-G17 | J17: =IF(I17<=0,"Yes","No") | K17: Documentation error | L17: 454 | M17: =TEXT(B17,"mmm-yy")
A18: SH0017 | B18: 46189.917 | C18: Independent Store | D18: Netherlands | E18: CD | F18: DPD | G18: 46198.917 | H18: 46198.917 | I18: =H18-G18 | J18: =IF(I18<=0,"Yes","No") | L18: 545 | M18: =TEXT(B18,"mmm-yy")
A19: SH0018 | B19: 46181.917 | C19: Online Retailer | D19: United States | E19: Merchandise | F19: UPS | G19: 46190.917 | H19: 46190.917 | I19: =H19-G19 | J19: =IF(I19<=0,"Yes","No") | L19: 601 | M19: =TEXT(B19,"mmm-yy")
A20: SH0019 | B20: 46204.917 | C20: Retail Chain | D20: Germany | E20: Vinyl | F20: PostNL | G20: 46209.917 | H20: 46209.917 | I20: =H20-G20 | J20: =IF(I20<=0,"Yes","No") | L20: 1059 | M20: =TEXT(B20,"mmm-yy")
A21: SH0020 | B21: 46156.917 | C21: Online Retailer | D21: Germany | E21: CD | F21: GLS | G21: 46162.917 | H21: 46161.917 | I21: =H21-G21 | J21: =IF(I21<=0,"Yes","No") | L21: 602 | M21: =TEXT(B21,"mmm-yy")
A22: SH0021 | B22: 46207.917 | C22: Independent Store | D22: United Kingdom | E22: Merchandise | F22: GLS | G22: 46214.917 | H22: 46218.917 | I22: =H22-G22 | J22: =IF(I22<=0,"Yes","No") | K22: Weather | L22: 156 | M22: =TEXT(B22,"mmm-yy")
A23: SH0022 | B23: 46243.917 | C23: Retail Chain | D23: France | E23: DVD | F23: DHL | G23: 46249.917 | H23: 46248.917 | I23: =H23-G23 | J23: =IF(I23<=0,"Yes","No") | L23: 1183 | M23: =TEXT(B23,"mmm-yy")
A24: SH0023 | B24: 46224.917 | C24: Independent Store | D24: Germany | E24: CD | F24: UPS | G24: 46229.917 | H24: 46228.917 | I24: =H24-G24 | J24: =IF(I24<=0,"Yes","No") | L24: 1295 | M24: =TEXT(B24,"mmm-yy")
A25: SH0024 | B25: 46169.917 | C25: Online Retailer | D25: Germany | E25: Vinyl | F25: DPD | G25: 46173.917 | H25: 46179.917 | I25: =H25-G25 | J25: =IF(I25<=0,"Yes","No") | K25: Stock shortage | L25: 1785 | M25: =TEXT(B25,"mmm-yy")
A26: SH0025 | B26: 46165.917 | C26: Online Retailer | D26: United States | E26: CD | F26: GLS | G26: 46170.917 | H26: 46178.917 | I26: =H26-G26 | J26: =IF(I26<=0,"Yes","No") | K26: Documentation error | L26: 84 | M26: =TEXT(B26,"mmm-yy")
A27: SH0026 | B27: 46146.917 | C27: Independent Store | D27: United Kingdom | E27: CD | F27: PostNL | G27: 46152.917 | H27: 46152.917 | I27: =H27-G27 | J27: =IF(I27<=0,"Yes","No") | L27: 712 | M27: =TEXT(B27,"mmm-yy")
A28: SH0027 | B28: 46134.917 | C28: Independent Store | D28: United States | E28: Merchandise | F28: PostNL | G28: 46144.917 | H28: 46144.917 | I28: =H28-G28 | J28: =IF(I28<=0,"Yes","No") | L28: 1304 | M28: =TEXT(B28,"mmm-yy")
A29: SH0028 | B29: 46153.917 | C29: Retail Chain | D29: Belgium | E29: Merchandise | F29: PostNL | G29: 46156.917 | H29: 46156.917 | I29: =H29-G29 | J29: =IF(I29<=0,"Yes","No") | L29: 543 | M29: =TEXT(B29,"mmm-yy")
A30: SH0029 | B30: 46236.917 | C30: Online Retailer | D30: Netherlands | E30: CD | F30: DHL | G30: 46246.917 | H30: 46251.917 | I30: =H30-G30 | J30: =IF(I30<=0,"Yes","No") | K30: Stock shortage | L30: 522 | M30: =TEXT(B30,"mmm-yy")
A31: SH0030 | B31: 46202.917 | C31: Retail Chain | D31: United States | E31: Vinyl | F31: DPD | G31: 46207.917 | H31: 46208.917 | I31: =H31-G31 | J31: =IF(I31<=0,"Yes","No") | K31: Carrier delay | L31: 1259 | M31: =TEXT(B31,"mmm-yy")
A32: SH0031 | B32: 46220.917 | C32: Retail Chain | D32: Belgium | E32: Merchandise | F32: PostNL | G32: 46229.917 | H32: 46228.917 | I32: =H32-G32 | J32: =IF(I32<=0,"Yes","No") | L32: 380 | M32: =TEXT(B32,"mmm-yy")
A33: SH0032 | B33: 46118.917 | C33: Independent Store | D33: United Kingdom | E33: Merchandise | F33: PostNL | G33: 46122.917 | H33: 46121.917 | I33: =H33-G33 | J33: =IF(I33<=0,"Yes","No") | L33: 780 | M33: =TEXT(B33,"mmm-yy")
A34: SH0033 | B34: 46149.917 | C34: Online Retailer | D34: Belgium | E34: CD | F34: UPS | G34: 46159.917 | H34: 46159.917 | I34: =H34-G34 | J34: =IF(I34<=0,"Yes","No") | L34: 1145 | M34: =TEXT(B34,"mmm-yy")
A35: SH0034 | B35: 46210.917 | C35: Retail Chain | D35: France | E35: CD | F35: GLS | G35: 46213.917 | H35: 46212.917 | I35: =H35-G35 | J35: =IF(I35<=0,"Yes","No") | L35: 155 | M35: =TEXT(B35,"mmm-yy")
A36: SH0035 | B36: 46201.917 | C36: Online Retailer | D36: Belgium | E36: DVD | F36: GLS | G36: 46204.917 | H36: 46203.917 | I36: =H36-G36 | J36: =IF(I36<=0,"Yes","No") | L36: 1764 | M36: =TEXT(B36,"mmm-yy")
A37: SH0036 | B37: 46156.917 | C37: Independent Store | D37: Netherlands | E37: Vinyl | F37: GLS | G37: 46166.917 | H37: 46169.917 | I37: =H37-G37 | J37: =IF(I37<=0,"Yes","No") | K37: Weather | L37: 1748 | M37: =TEXT(B37,"mmm-yy")
A38: SH0037 | B38: 46246.917 | C38: Independent Store | D38: United States | E38: CD | F38: DHL | G38: 46255.917 | H38: 46254.917 | I38: =H38-G38 | J38: =IF(I38<=0,"Yes","No") | L38: 1523 | M38: =TEXT(B38,"mmm-yy")
A39: SH0038 | B39: 46191.917 | C39: Online Retailer | D39: France | E39: CD | F39: PostNL | G39: 46196.917 | H39: 46196.917 | I39: =H39-G39 | J39: =IF(I39<=0,"Yes","No") | L39: 383 | M39: =TEXT(B39,"mmm-yy")
A40: SH0039 | B40: 46234.917 | C40: Independent Store | D40: Netherlands | E40: Merchandise | F40: DPD | G40: 46242.917 | H40: 46241.917 | I40: =H40-G40 | J40: =IF(I40<=0,"Yes","No") | L40: 524 | M40: =TEXT(B40,"mmm-yy")
...

Sheet Dashboard
A1: Bertus Delivery Performance Dashboard (mock data, personal practice project)
A2: Modeled on Bertus Distributie B.V. physical media wholesale operations. All figures are synthetic.
A4: Total shipments | B4: On time delivery rate | C4: Average delay (late shipments) | D4: Total order value EUR
A5: =COUNTA('Raw Data'!A2:A141) | B5: =COUNTIF('Raw Data'!J2:J141,"Yes")/COUNTA('Raw Data'!J2:J141) | C5: =AVERAGEIF('Raw Data'!I2:I141,">0") | D5: =SUM('Raw Data'!L2:L141)
A8: Delay reason breakdown
A9: Delay reason | B9: Count | C9: Share of delayed shipments
A10: Carrier delay | B10: =COUNTIF('Raw Data'!K2:K141,"Carrier delay") | C10: =B10/COUNTIF('Raw Data'!J2:J141,"No")
A11: Customs hold | B11: =COUNTIF('Raw Data'!K2:K141,"Customs hold") | C11: =B11/COUNTIF('Raw Data'!J2:J141,"No")
A12: Stock shortage | B12: =COUNTIF('Raw Data'!K2:K141,"Stock shortage") | C12: =B12/COUNTIF('Raw Data'!J2:J141,"No")
A13: Documentation error | B13: =COUNTIF('Raw Data'!K2:K141,"Documentation error") | C13: =B13/COUNTIF('Raw Data'!J2:J141,"No")
A14: Weather | B14: =COUNTIF('Raw Data'!K2:K141,"Weather") | C14: =B14/COUNTIF('Raw Data'!J2:J141,"No")
A17: Carrier performance
A18: Carrier | B18: Shipments | C18: On time rate | D18: Avg delay (days)
A19: PostNL | B19: =COUNTIF('Raw Data'!F2:F141,"PostNL") | C19: =COUNTIFS('Raw Data'!F2:F141,"PostNL",'Raw Data'!J2:J141,"Yes")/B19 | D19: =AVERAGEIFS('Raw Data'!I2:I141,'Raw Data'!F2:F141,"PostNL",'Raw Data'!I2:I141,">0")
A20: DHL | B20: =COUNTIF('Raw Data'!F2:F141,"DHL") | C20: =COUNTIFS('Raw Data'!F2:F141,"DHL",'Raw Data'!J2:J141,"Yes")/B20 | D20: =AVERAGEIFS('Raw Data'!I2:I141,'Raw Data'!F2:F141,"DHL",'Raw Data'!I2:I141,">0")
A21: DPD | B21: =COUNTIF('Raw Data'!F2:F141,"DPD") | C21: =COUNTIFS('Raw Data'!F2:F141,"DPD",'Raw Data'!J2:J141,"Yes")/B21 | D21: =AVERAGEIFS('Raw Data'!I2:I141,'Raw Data'!F2:F141,"DPD",'Raw Data'!I2:I141,">0")
A22: GLS | B22: =COUNTIF('Raw Data'!F2:F141,"GLS") | C22: =COUNTIFS('Raw Data'!F2:F141,"GLS",'Raw Data'!J2:J141,"Yes")/B22 | D22: =AVERAGEIFS('Raw Data'!I2:I141,'Raw Data'!F2:F141,"GLS",'Raw Data'!I2:I141,">0")
A23: UPS | B23: =COUNTIF('Raw Data'!F2:F141,"UPS") | C23: =COUNTIFS('Raw Data'!F2:F141,"UPS",'Raw Data'!J2:J141,"Yes")/B23 | D23: =AVERAGEIFS('Raw Data'!I2:I141,'Raw Data'!F2:F141,"UPS",'Raw Data'!I2:I141,">0")
A26: Monthly trend
A27: Month | B27: Shipments | C27: On time rate
A28: Apr-26 | B28: =COUNTIF('Raw Data'!M2:M141,"Apr-26") | C28: =COUNTIFS('Raw Data'!M2:M141,"Apr-26",'Raw Data'!J2:J141,"Yes")/B28
A29: May-26 | B29: =COUNTIF('Raw Data'!M2:M141,"May-26") | C29: =COUNTIFS('Raw Data'!M2:M141,"May-26",'Raw Data'!J2:J141,"Yes")/B29
A30: Jun-26 | B30: =COUNTIF('Raw Data'!M2:M141,"Jun-26") | C30: =COUNTIFS('Raw Data'!M2:M141,"Jun-26",'Raw Data'!J2:J141,"Yes")/B30
A31: Jul-26 | B31: =COUNTIF('Raw Data'!M2:M141,"Jul-26") | C31: =COUNTIFS('Raw Data'!M2:M141,"Jul-26",'Raw Data'!J2:J141,"Yes")/B31
A32: Aug-26 | B32: =COUNTIF('Raw Data'!M2:M141,"Aug-26") | C32: =COUNTIFS('Raw Data'!M2:M141,"Aug-26",'Raw Data'!J2:J141,"Yes")/B32
A34: How to finish the visuals (2 minutes)
A35: 1. Select A9:C15 and insert a bar chart for delay reason breakdown (this is the direct proof point for the shared delay log improvement idea).
A36: 2. Select A18:D23 and insert a bar chart for carrier performance, sort by on time rate to spot the weakest carrier at a glance.
A37: 3. Select A27:C32 and insert a line chart for the monthly trend to show whether reliability is improving or slipping over time.
A38: 4. All numbers above are formulas referencing Raw Data, so if you edit or extend Raw Data (or replace it with a real dataset later), the whole dashboard recalculates itself.
